Workbook

Sheet Dec 2024
A1: Month | B1: Sales person | C1: Order Date | D1: Week | E1: Company Name | F1: Selling price | G1: Type Of Gift | H1: Business Type | I1: Cost price | J1: Margin | K1: Profit | L1: Payment status | M1: Order No | N1: Note
A2: Dec | B2: Tamer | C2: 45636 | E2: Tm Done | F2: 4.73 | G2: Flowers | I2: 2 | J2: =(Table3[[#This Row],[Selling price]]-Table3[[#This Row],[Cost price]])/Table3[[#This Row],[Selling price]] -> 0.57716702 | K2: =Table3[[#This Row],[Selling price]]-Table3[[#This Row],[Cost price]] -> 2.73 | L2: Not paid | M2: 12307504
A3: Dec | B3: Tamer | C3: 45636 | E3: Tm Done | F3: 15.75 | G3: Flowers | J3: =(Table3[[#This Row],[Selling price]]-Table3[[#This Row],[Cost price]])/Table3[[#This Row],[Selling price]] -> 1 | K3: =Table3[[#This Row],[Selling price]]-Table3[[#This Row],[Cost price]] -> 15.75 | L3: Not paid | M3: 12307437
A4: Dec | B4: Tamer | C4: 45636 | E4: Tm Done | F4: 4.73 | G4: Flowers | J4: =(Table3[[#This Row],[Selling price]]-Table3[[#This Row],[Cost price]])/Table3[[#This Row],[Selling price]] -> 1 | K4: =Table3[[#This Row],[Selling price]]-Table3[[#This Row],[Cost price]] -> 4.73 | L4: Not paid | M4: 12307204
A5: Dec | B5: Tamer | C5: 45636 | E5: Tm Done | F5: 4.73 | G5: Flowers | J5: =(Table3[[#This Row],[Selling price]]-Table3[[#This Row],[Cost price]])/Table3[[#This Row],[Selling price]] -> 1 | K5: =Table3[[#This Row],[Selling price]]-Table3[[#This Row],[Cost price]] -> 4.73 | M5: 12307466
A6: Dec | B6: Tamer | C6: 45636 | E6: Tm Done | F6: 4.73 | G6: Flowers | J6: =(Table3[[#This Row],[Selling price]]-Table3[[#This Row],[Cost price]])/Table3[[#This Row],[Selling price]] -> 1 | K6: =Table3[[#This Row],[Selling price]]-Table3[[#This Row],[Cost price]] -> 4.73 | M6: 12307367
A7: Dec | B7: Tamer | C7: 24/12/2024 | E7: Al Roya Newspaper | F7: 365.4 | G7: Flowers | H7: Event | J7: =(Table3[[#This Row],[Selling price]]-Table3[[#This Row],[Cost price]])/Table3[[#This Row],[Selling price]] -> 1 | K7: =Table3[[#This Row],[Selling price]]-Table3[[#This Row],[Cost price]] -> 365.4 | L7: Not paid | M7: 12454777
A8: Dec | B8: Tamer | C8: 24/12/2024 | E8: Oman Human Rights Commision | F8: 93.15 | G8: Flowers | H8: Event | J8: =(Table3[[#This Row],[Selling price]]-Table3[[#This Row],[Cost price]])/Table3[[#This Row],[Selling price]] -> 1 | K8: =Table3[[#This Row],[Selling price]]-Table3[[#This Row],[Cost price]] -> 93.15 | L8: paid | M8: 12450632
A9: Dec | B9: Tamer | C9: 25/12/2024 | E9: Bowsher Endowments Foundation | F9: 425.25 | G9: Flowers | H9: Event | J9: =(Table3[[#This Row],[Selling price]]-Table3[[#This Row],[Cost price]])/Table3[[#This Row],[Selling price]] -> 1 | K9: =Table3[[#This Row],[Selling price]]-Table3[[#This Row],[Cost price]] -> 425.25 | L9: Paid | M9: 12461954
A10: Dec | B10: Tamer | C10: 26/12/2024 | E10: Walk in | F10: 14 | G10: Flowers | H10: Walk in | K10: =Table3[[#This Row],[Selling price]]-Table3[[#This Row],[Cost price]] -> 14 | L10: Paid | M10: 12483225
A11: Dec | B11: Tamer | C11: 26/12/2024 | E11: Swiss Arabian | F11: 55.125 | G11: Flowers | H11: Event | K11: =Table3[[#This Row],[Selling price]]-Table3[[#This Row],[Cost price]] -> 55.125 | L11: Paid | M11: 12482912
A12: Dec | B12: Tamer | C12: 26/12/2024 | E12: Ominvest | F12: 46.75 | G12: Flowers & Chocolate | H12: Birthday | K12: =Table3[[#This Row],[Selling price]]-Table3[[#This Row],[Cost price]] -> 46.75 | L12: Paid | M12: 12480675
A13: Dec | B13: Tamer | C13: 26/12/2024 | E13: Sohar Univeristy Graduation | F13: 416.5 | G13: Flowers | H13: Graduation | K13: =Table3[[#This Row],[Selling price]]-Table3[[#This Row],[Cost price]] -> 416.5 | L13: Paid | M13: 12479785
A14: Dec | B14: Tamer | C14: 26/12/2024 | E14: Walk in | F14: 39.85 | G14: Flowers | H14: Walk in | K14: =Table3[[#This Row],[Selling price]]-Table3[[#This Row],[Cost price]] -> 39.85 | L14: Paid | M14: 12468902
A16: Total | F16: =SUBTOTAL(109,Table3[Selling price]) -> 1490.695 | J16: =SUBTOTAL(101,Table3[[Margin ]]) -> 0.94714588 | K16: =SUBTOTAL(109,Table3[[Profit ]]) -> 1488.695

Sheet Pivot
A3: Sum of Selling price | B3: Column Labels
A4: Row Labels | B4: W1 | C4: W2 | D4: W3 | E4: #N/A | F4: Grand Total
A5: 3PL | C5: 103.245 | F5: 103.245
A6: Event | C6: 440 | D6: 336.175 | F6: 776.175
A7: Gifting | B7: 7639.125 | C7: 246.45 | D7: 127.35 | F7: 8012.925
A8: (blank)
A9: Grand Total | B9: 7639.125 | C9: 789.695 | D9: 463.525 | F9: 8892.345

Sheet FEB 2025
A1: Month | B1: Sales person | C1: Order Date | D1: Week | E1: Company Name | F1: Selling price | G1: Type | H1: Type Of Gift | I1: Business Type | J1: Cost price | K1: Margin | L1: Profit | M1: Payment status | N1: Delivery Status | O1: Order No | P1: Note
A2: Feb | B2: Tamer | C2: 45691 | D2: =VLOOKUP(Table323[[#This Row],[Order Date]],'Calendars '!A1:C368,2,) -> W6 | E2: NN Graduation Ceremony | F2: 249 | G2: Event | H2: Flowers | I2: Corporate | M2: Paid | N2: Deliverd | O2: 12893257 | P2: Graduation offline Sale
A3: Feb | B3: Tamer | C3: 45695 | D3: =VLOOKUP(Table323[[#This Row],[Order Date]],'Calendars '!A2:C369,2,) -> W6 | E3: Umima | F3: 263.55 | G3: Event | H3: Flowers | I3: wedding | M3: paid | N3: Deliverd | O3: 12976808 | P3: wedding
A4: Feb | B4: Tamer | C4: 45695 | D4: =VLOOKUP(Table323[[#This Row],[Order Date]],'Calendars '!A3:C370,2,) -> W6 | E4: House Of Poineer | F4: 861 | G4: Event | H4: Flowers & Chocolate | I4: Event | O4: 13233795
A5: Feb | B5: Tamer | C5: 45697 | D5: =VLOOKUP(Table323[[#This Row],[Order Date]],'Calendars '!A4:C371,2,) -> W7 | E5: Ominvest | F5: 44 | G5: Gifting | H5: Flowers & Chocolate | I5: Corporate | N5: Deliverd | O5: 12971516
A6: Feb | B6: Tamer | C6: 45697 | D6: =VLOOKUP(Table323[[#This Row],[Order Date]],'Calendars '!A8:C375,2,) -> W7 | E6: NBO | F6: 20.25 | G6: Event | H6: Flowers | I6: Event | N6: Deliverd | O6: 12977256
A7: Feb | B7: Tamer | C7: 45698 | D7: =VLOOKUP(Table323[[#This Row],[Order Date]],'Calendars '!A5:C372,2,) -> W7 | E7: Omna Medical Graduation Ceremony | F7: 156 | G7: Event | H7: Flowers | I7: Graduation | M7: Paid | N7: Deliverd | O7: 12988636
A8: Feb | B8: Tamer | C8: 45698 | D8: =VLOOKUP(Table323[[#This Row],[Order Date]],'Calendars '!A6:C373,2,) -> W7 | E8: T.D | F8: 14 | G8: 3PL | H8: Flowers | I8: 3PL | N8: Deliverd | O8: 12990364
A9: Feb | B9: Tamer | C9: 45699 | D9: =VLOOKUP(Table323[[#This Row],[Order Date]],'Calendars '!A7:C374,2,) -> W7 | E9: Walk in | F9: 9 | G9: Walk in | H9: Flowers | M9: Paid | N9: Deliverd | O9: 13003431
A10: Feb | B10: Tamer | C10: 45700 | D10: =VLOOKUP(Table323[[#This Row],[Order Date]],'Calendars '!A9:C376,2,) -> W7 | E10: Al Abrar | F10: 60 | G10: Event | H10: Flowers | I10: Event | M10: Paid | N10: Deliverd | O10: 13019652
A11: Feb | B11: Tamer | C11: 45701 | D11: =VLOOKUP(Table323[[#This Row],[Order Date]],'Calendars '!A10:C377,2,) -> W7 | E11: Walk in | F11: 20.6 | G11: Walk in | H11: Walk in | I11: VD Offline | M11: Paid | N11: Deliverd | O11: 13039241
A12: Feb | B12: Tamer | C12: 45702 | D12: =VLOOKUP(Table323[[#This Row],[Order Date]],'Calendars '!A11:C378,2,) -> W7 | E12: Offline Sales | F12: 60 | G12: Walk in | H12: Walk in | I12: VD Offline | M12: Paid | N12: Deliverd | O12: 13165239
A13: Feb | B13: Tamer | C13: 45705 | D13: =VLOOKUP(Table323[[#This Row],[Order Date]],'Calendars '!A12:C379,2,) -> W8 | E13: Offline Sales | F13: 25 | G13: Walk in | H13: Walk in | I13: VD Offline | M13: Paid | N13: Deliverd | O13: 13165367
A14: Feb | B14: Tamer | C14: 45705 | D14: =VLOOKUP(Table323[[#This Row],[Order Date]],'Calendars '!A13:C380,2,) -> W8 | E14: Offline Sales | F14: 102.5 | G14: Walk in | H14: Walk in | I14: VD Offline | M14: Paid | N14: Deliverd | O14: 13165413
A15: Feb | B15: Tamer | C15: 45705 | D15: =VLOOKUP(Table323[[#This Row],[Order Date]],'Calendars '!A14:C381,2,) -> W8 | E15: Offline Sales | F15: 37 | G15: Walk in | H15: Walk in | I15: VD Offline | M15: Paid | N15: Deliverd | O15: 13165502
A16: Feb | B16: Tamer | C16: 45705 | D16: =VLOOKUP(Table323[[#This Row],[Order Date]],'Calendars '!A15:C382,2,) -> W8 | E16: Offline Sales | F16: 107 | G16: Walk in | H16: Walk in | I16: VD Offline | M16: Paid | N16: Deliverd | O16: 13165598
A17: Feb | B17: Tamer | C17: 45705 | D17: =VLOOKUP(Table323[[#This Row],[Order Date]],'Calendars '!A16:C383,2,) -> W8 | E17: Offline Sales | F17: 82.5 | G17: Walk in | H17: Walk in | I17: VD Offline | M17: Paid | N17: Deliverd | O17: 13165624
A18: Feb | B18: Tamer | C18: 45705 | D18: =VLOOKUP(Table323[[#This Row],[Order Date]],'Calendars '!A17:C384,2,) -> W8 | E18: Offline Sales | F18: 15 | G18: Walk in | H18: Walk in | I18: VD Offline | M18: Paid | N18: Deliverd | O18: 13167174
A19: Feb | B19: Tamer | C19: 45705 | D19: =VLOOKUP(Table323[[#This Row],[Order Date]],'Calendars '!A17:C384,2,) -> W8 | E19: Offline Sales | F19: 19 | G19: Walk in | H19: Walk in | I19: VD Offline | M19: Paid | N19: Deliverd | O19: 13165286
A20: Feb | B20: Tamer | C20: 45705 | D20: =VLOOKUP(Table323[[#This Row],[Order Date]],'Calendars '!A17:C384,2,) -> W8 | E20: Offline Sales | F20: 53 | G20: Walk in | H20: Walk in | I20: VD Offline | M20: Paid | N20: Deliverd | O20: 13172126
A21: Feb | B21: Tamer | C21: 45705 | D21: =VLOOKUP(Table323[[#This Row],[Order Date]],'Calendars '!A17:C384,2,) -> W8 | E21: Offline Sales | F21: 54 | G21: Walk in | H21: Walk in | I21: VD Offline | M21: Paid | N21: Deliverd | O21: 13171885
A22: Feb | B22: Tamer | C22: 45705 | D22: =VLOOKUP(Table323[[#This Row],[Order Date]],'Calendars '!A18:C385,2,) -> W8 | E22: Offline Sales | F22: 22 | G22: Walk in | H22: Walk in | I22: VD Offline | M22: Paid | N22: Deliverd | O22: 13171652
A23: Feb | B23: Tamer | C23: 45705 | D23: =VLOOKUP(Table323[[#This Row],[Order Date]],'Calendars '!A19:C386,2,) -> W8 | E23: Offline Sales | F23: 20 | G23: Walk in | H23: Walk in | I23: VD Offline | M23: Paid | N23: Deliverd | O23: 13171732
A24: Feb | B24: Tamer | C24: 45705 | D24: =VLOOKUP(Table323[[#This Row],[Order Date]],'Calendars '!A19:C386,2,) -> W8 | E24: Offline Sales | F24: 102 | G24: Walk in | H24: Walk in | I24: VD Offline | M24: Paid | N24: Deliverd | O24: 13171779
A25: Feb | B25: Tamer | C25: 45706 | D25: =VLOOKUP(Table323[[#This Row],[Order Date]],'Calendars '!A20:C387,2,) -> W8 | E25: Offline Sales | F25: 12.05 | G25: Walk in | H25: Walk in | I25: VD Offline | M25: Paid | N25: Deliverd | O25: 13178782
A26: Feb | B26: Tamer | C26: 45705 | D26: =VLOOKUP(Table323[[#This Row],[Order Date]],'Calendars '!A12:C379,2,) -> W8 | E26: NBO | F26: 30 | G26: Event | H26: Flowers | I26: Event | N26: Deliverd | O26: 13171457
A27: Feb | B27: Tamer | C27: 45706 | D27: =VLOOKUP(Table323[[#This Row],[Order Date]],'Calendars '!A13:C380,2,) -> W8 | E27: OHR | F27: 68.25 | G27: Event | H27: Flowers | I27: Event | N27: Deliverd | O27: 13177286
A28: Feb | B28: Tamer | C28: 45706 | D28: =VLOOKUP(Table323[[#This Row],[Order Date]],'Calendars '!A14:C381,2,) -> W8 | E28: Styles Salalah | F28: 210 | G28: Event | H28: Flowers | I28: Event | N28: Deliverd | O28: 13177272
A29: Feb | B29: Tamer | C29: 45707 | D29: =VLOOKUP(Table323[[#This Row],[Order Date]],'Calendars '!A15:C382,2,) -> W8 | E29: Styles Muscat Event | F29: 142.1 | G29: Event | H29: Flowers | I29: Event | N29: Deliverd | O29: 13189756
A30: Feb | B30: Tamer | C30: 45708 | D30: =VLOOKUP(Table323[[#This Row],[Order Date]],'Calendars '!A16:C383,2,) -> W8 | E30: Al Roya | F30: 68.25 | G30: Event | H30: Flowers | I30: Event | N30: Deliverd | O30: 13195385
A31: Feb | B31: Tamer | C31: 45708 | D31: =VLOOKUP(Table323[[#This Row],[Order Date]],'Calendars '!A17:C384,2,) -> W8 | E31: ODP | F31: 131.25 | G31: Gifting | H31: Chocolate | I31: Corporate | N31: Deliverd | O31: 13195972
A32: Feb | B32: Tamer | C32: 45710 | D32: =VLOOKUP(Table323[[#This Row],[Order Date]],'Calendars '!A18:C385,2,) -> W8 | E32: Walk in | F32: 139 | G32: Walk in | H32: Flowers | I32: Walk in | M32: Paid | N32: Deliverd | O32: 13213446
A33: Feb | B33: Tamer | C33: 45711 | D33: =VLOOKUP(Table323[[#This Row],[Order Date]],'Calendars '!A19:C386,2,) -> W9 | E33: Styles of Event | F33: 52.225 | G33: Event | H33: Flowers | I33: Event | N33: Deliverd | O33: 13220028
A34: Feb | B34: Tamer | C34: 45712 | D34: =VLOOKUP(Table323[[#This Row],[Order Date]],'Calendars '!A20:C387,2,) -> W9 | E34: NBO | F34: 50.25 | G34: Event | H34: Chocolate | I34: Event | N34: Deliverd | O34: 13228207
A35: Feb | B35: Tamer | C35: 45713 | D35: =VLOOKUP(Table323[[#This Row],[Order Date]],'Calendars '!A21:C388,2,) -> W9 | E35: Al Khanjar | F35: 55.125 | G35: Gifting | H35: Flowers | I35: Corporate | N35: Deliverd | O35: 13239553
A36: Feb | B36: Tamer | C36: 45714 | D36: =VLOOKUP(Table323[[#This Row],[Order Date]],'Calendars '!A22:C389,2,) -> W9 | E36: Offline Sales | F36: 111.5 | G36: Walk in | H36: Flowers | I36: Walk in | M36: Paid | N36: Deliverd | O36: 13250879
A37: Feb | B37: Tamer | C37: 45714 | D37: =VLOOKUP(Table323[[#This Row],[Order Date]],'Calendars '!A23:C390,2,) -> W9 | E37: Offline Sales | F37: 53.1 | G37: Walk in | H37: Flowers | I37: Walk in | M37: Paid | N37: Deliverd | O37: 13250442
A38: Feb | B38: Tamer | C38: 45714 | D38: =VLOOKUP(Table323[[#This Row],[Order Date]],'Calendars '!A24:C391,2,) -> W9 | E38: House Of Poineer | F38: 43.575 | G38: Gifting | H38: Flowers | I38: Corporate | N38: Deliverd | O38: 13241924
A39: Jan | B39: Tamer | C39: 45714 | D39: =VLOOKUP(Table323[[#This Row],[Order Date]],'Calendars '!A25:C392,2,) -> W9 | E39: Nortal LLC | F39: 559.125 | G39: Gifting | H39: Flowers & Chocolate | I39: Corporate | M39: Paid | N39: Deliverd | O39: 13238741
A40: Jan | B40: Tamer | C40: 45715 | D40: =VLOOKUP(Table323[[#This Row],[Order Date]],'Calendars '!A26:C393,2,) -> W9 | E40: T.D | F40: 18.38 | G40: 3PL | H40: Flowers | I40: 3PL | N40: Deliverd | O40: 13263217
...

Sheet Sheet1

Sheet JAN 2025
A1: Month | B1: Sales person | C1: Order Date | D1: Week | E1: Company Name | F1: Selling price | G1: Type | H1: Type Of Gift | I1: Business Type | J1: Cost price | K1: Margin | L1: Profit | M1: Payment status | N1: Delivery Status | O1: Order No | P1: Note
A2: Jan | B2: Tamer | C2: 45658 | D2: =VLOOKUP(Table32[[#This Row],[Order Date]],'Calendars '!A2:C369,2,) -> W1 | E2: ABQ Education Group 1 | F2: 3113.25 | G2: Gifting | H2: Flowers & Chocolate | I2: Corporate | J2: 1700 | K2: =(Table32[[#This Row],[Selling price]]-Table32[[#This Row],[Cost price]])/Table32[[#This Row],[Selling price]] -> 0.45394684 | L2: =Table3[[#This Row],[Selling price]]-Table3[[#This Row],[Cost price]] -> 2.73 | M2: 50% Paid | N2: Delivery will be madeon Feb | P2: ABQ Chocolate Order
A3: Jan | B3: Tamer | C3: 45658 | D3: =VLOOKUP(Table32[[#This Row],[Order Date]],'Calendars '!A3:C370,2,) -> W1 | E3: ABQ Education Group 2 | F3: 4331.25 | G3: Gifting | H3: Chocolate | I3: Corporate | J3: 2250 | K3: =(Table32[[#This Row],[Selling price]]-Table32[[#This Row],[Cost price]])/Table32[[#This Row],[Selling price]] -> 0.48051948 | L3: =Table3[[#This Row],[Selling price]]-Table3[[#This Row],[Cost price]] -> 15.75 | N3: Delivery will be made within the year | O3: 12564735 | P3: ABQ Order multiple recipients
A4: Jan | B4: Tamer | C4: 45659 | D4: =VLOOKUP(Table32[[#This Row],[Order Date]],'Calendars '!A4:C371,2,) -> W1 | E4: Omna Football Assosation | F4: 157 | G4: Gifting | H4: Flowers & Chocolate | I4: Corporate | J4: 120 | K4: =(Table32[[#This Row],[Selling price]]-Table32[[#This Row],[Cost price]])/Table32[[#This Row],[Selling price]] -> 0.23566879 | L4: =Table3[[#This Row],[Selling price]]-Table3[[#This Row],[Cost price]] -> 4.73 | N4: Deliverd in Kwaite | P4: Kwaite Order
A5: Jan | B5: Tamer | C5: 45662 | D5: =VLOOKUP(Table32[[#This Row],[Order Date]],'Calendars '!A5:C372,2,) -> W2 | E5: Marca | F5: 440 | G5: Event | H5: Chocolate | I5: Corporate | J5: 318.6 | K5: =(Table32[[#This Row],[Selling price]]-Table32[[#This Row],[Cost price]])/Table32[[#This Row],[Selling price]] -> 0.27590909 | L5: =Table3[[#This Row],[Selling price]]-Table3[[#This Row],[Cost price]] -> 4.73 | N5: Deliverd | O5: 12635378 | P5: Marca Order multiple recipients
A6: Jan | B6: Tamer | C6: 45662 | D6: =VLOOKUP(Table32[[#This Row],[Order Date]],'Calendars '!A6:C373,2,) -> W2 | E6: Kenshō Mindful Communications | F6: 90 | G6: Gifting | H6: Flowers & Chocolate | I6: Corporate | J6: 70 | K6: =(Table32[[#This Row],[Selling price]]-Table32[[#This Row],[Cost price]])/Table32[[#This Row],[Selling price]] -> 0.22222222 | L6: =Table3[[#This Row],[Selling price]]-Table3[[#This Row],[Cost price]] -> 4.73 | M6: Paid | N6: Deliverd in KSA | P6: KSA Order
A7: Jan | B7: Tamer | C7: 45662 | D7: =VLOOKUP(Table32[[#This Row],[Order Date]],'Calendars '!A7:C374,2,) -> W2 | E7: Oman Data Park | F7: 57.75 | G7: Gifting | H7: Flowers | I7: Corporate | K7: =(Table32[[#This Row],[Selling price]]-Table32[[#This Row],[Cost price]])/Table32[[#This Row],[Selling price]] -> 1 | L7: =Table3[[#This Row],[Selling price]]-Table3[[#This Row],[Cost price]] -> 365.4 | N7: Deliverd | O7: 12646365
A8: Jan | B8: Tamer | C8: 45663 | D8: =VLOOKUP(Table32[[#This Row],[Order Date]],'Calendars '!A8:C375,2,) -> W2 | E8: Ominvest | F8: 29.7 | G8: Gifting | H8: Flowers & Chocolate | I8: Corporate | K8: =(Table32[[#This Row],[Selling price]]-Table32[[#This Row],[Cost price]])/Table32[[#This Row],[Selling price]] -> 1 | L8: =Table3[[#This Row],[Selling price]]-Table3[[#This Row],[Cost price]] -> 93.15 | M8: Paid | N8: Deliverd | O8: 12645154
A9: Jan | B9: Tamer | C9: 45663 | D9: =VLOOKUP(Table32[[#This Row],[Order Date]],'Calendars '!A9:C376,2,) -> W2 | E9: FAB Bank | F9: 24 | G9: Gifting | H9: Flowers | I9: Corporate | K9: =(Table32[[#This Row],[Selling price]]-Table32[[#This Row],[Cost price]])/Table32[[#This Row],[Selling price]] -> 1 | L9: =Table3[[#This Row],[Selling price]]-Table3[[#This Row],[Cost price]] -> 425.25 | N9: Deliverd | O9: 12638124
A10: Jan | B10: Tamer | C10: 45663 | D10: =VLOOKUP(Table32[[#This Row],[Order Date]],'Calendars '!A10:C377,2,) -> W2 | E10: Tm Done | F10: 68.26 | G10: 3PL | H10: Flowers | I10: 3PL | L10: =Table3[[#This Row],[Selling price]]-Table3[[#This Row],[Cost price]] -> 14 | N10: Deliverd | O10: 12655652
A11: Jan | B11: Tamer | C11: 45664 | D11: =VLOOKUP(Table32[[#This Row],[Order Date]],'Calendars '!A11:C378,2,) -> W2 | E11: walk in | F11: 15 | G11: Gifting | H11: Flowers | I11: walk in | L11: =Table3[[#This Row],[Selling price]]-Table3[[#This Row],[Cost price]] -> 55.125 | M11: Paid | N11: Deliverd | O11: 12667261 | P11: To Fatma POS
A12: Jan | B12: Tamer | C12: 45665 | D12: =VLOOKUP(Table32[[#This Row],[Order Date]],'Calendars '!A12:C379,2,) -> W2 | E12: Tm Done | F12: 34.985 | G12: 3PL | H12: Flowers | I12: 3PL | K12: =(Table32[[#This Row],[Selling price]]-Table32[[#This Row],[Cost price]])/Table32[[#This Row],[Selling price]] -> 1 | L12: =Table3[[#This Row],[Selling price]]-Table3[[#This Row],[Cost price]] -> 46.75 | N12: Deliverd | O12: 12676931
A13: Jan | B13: Tamer | C13: 45666 | D13: =VLOOKUP(Table32[[#This Row],[Order Date]],'Calendars '!A13:C380,2,) -> W2 | E13: Ominvest | F13: 30 | G13: Gifting | H13: Flowers & Chocolate | I13: Corporate | K13: =(Table32[[#This Row],[Selling price]]-Table32[[#This Row],[Cost price]])/Table32[[#This Row],[Selling price]] -> 1 | L13: =Table3[[#This Row],[Selling price]]-Table3[[#This Row],[Cost price]] -> 416.5 | M13: Paid | N13: Deliverd | O13: 12709104
A14: Jan | B14: Tamer | C14: 45671 | D14: =VLOOKUP(Table32[[#This Row],[Order Date]],'Calendars '!A14:C381,2,) -> W3 | E14: walk in | F14: 15 | G14: Gifting | H14: Flowers | I14: walk in | K14: =(Table32[[#This Row],[Selling price]]-Table32[[#This Row],[Cost price]])/Table32[[#This Row],[Selling price]] -> 1 | L14: =Table3[[#This Row],[Selling price]]-Table3[[#This Row],[Cost price]] -> 39.85 | M14: Paid | N14: Deliverd | O14: 12718837 | P14: To Fatma POS
A15: Jan | B15: Tamer | C15: 45671 | D15: =VLOOKUP(Table32[[#This Row],[Order Date]],'Calendars '!A15:C382,2,) -> W3 | E15: Mohamed Al Yahmadi OFA | F15: 50.625 | G15: Gifting | H15: Flowers & Chocolate | I15: Corporate | K15: =(Table32[[#This Row],[Selling price]]-Table32[[#This Row],[Cost price]])/Table32[[#This Row],[Selling price]] -> 1 | L15: =Table3[[#This Row],[Selling price]]-Table3[[#This Row],[Cost price]] -> 0 | N15: Deliverd | O15: 12717115
A16: Jan | B16: Tamer | C16: 45672 | D16: =VLOOKUP(Table32[[#This Row],[Order Date]],'Calendars '!A16:C383,2,) -> W3 | E16: Ominvest | F16: 204.4 | G16: Event | H16: Chocolate | I16: Corporate | L16: =Table3[[#This Row],[Selling price]]-Table3[[#This Row],[Cost price]] -> #VALUE! | M16: Paid | N16: Deliverd | O16: 12735862
A17: Jan | B17: Tamer | C17: 45672 | D17: =VLOOKUP(Table32[[#This Row],[Order Date]],'Calendars '!A17:C384,2,) -> W3 | E17: walk in | F17: 15 | G17: Gifting | H17: Flowers | I17: walk in | K17: =(Table32[[#This Row],[Selling price]]-Table32[[#This Row],[Cost price]])/Table32[[#This Row],[Selling price]] -> 1 | L17: =Table3[[#This Row],[Selling price]]-Table3[[#This Row],[Cost price]] -> #VALUE! | M17: Paid (Tamer Account ) | N17: Deliverd | O17: 12724178 | P17: Wadad Brother
A18: Jan | B18: Tamer | C18: 45673 | D18: =VLOOKUP(Table32[[#This Row],[Order Date]],'Calendars '!A18:C385,2,) -> W3 | E18: Styles Event | F18: 76.125 | G18: Event | H18: Flowers | I18: Event | K18: =(Table32[[#This Row],[Selling price]]-Table32[[#This Row],[Cost price]])/Table32[[#This Row],[Selling price]] -> 1 | L18: =Table3[[#This Row],[Selling price]]-Table3[[#This Row],[Cost price]] -> #VALUE! | N18: Deliverd | O18: 12717270
A19: Jan | B19: Tamer | C19: 45674 | D19: =VLOOKUP(Table32[[#This Row],[Order Date]],'Calendars '!A19:C386,2,) -> W3 | E19: Ooredoo | F19: 46.725 | G19: Gifting | H19: Flowers | I19: Corporate | K19: =(Table32[[#This Row],[Selling price]]-Table32[[#This Row],[Cost price]])/Table32[[#This Row],[Selling price]] -> 1 | L19: =Table3[[#This Row],[Selling price]]-Table3[[#This Row],[Cost price]] -> #VALUE! | N19: Deliverd | O19: 12743396
A20: Jan | B20: Tamer | C20: 45675 | D20: =VLOOKUP(Table32[[#This Row],[Order Date]],'Calendars '!A20:C387,2,) -> W3 | E20: OHRC | F20: 55.65 | G20: Event | H20: Flowers | I20: Gov | K20: =(Table32[[#This Row],[Selling price]]-Table32[[#This Row],[Cost price]])/Table32[[#This Row],[Selling price]] -> 1 | L20: =Table3[[#This Row],[Selling price]]-Table3[[#This Row],[Cost price]] -> #VALUE! | N20: Deliverd | O20: 12751373
A21: Jan | B21: Tamer | C21: 45677 | D21: =VLOOKUP(Table32[[#This Row],[Order Date]],'Calendars '!A22:C389,2,) -> W4 | E21: Tm Done | F21: 6.3 | G21: 3PL | H21: Flowers | I21: 3PL | K21: =(Table32[[#This Row],[Selling price]]-Table32[[#This Row],[Cost price]])/Table32[[#This Row],[Selling price]] -> 1 | L21: =Table3[[#This Row],[Selling price]]-Table3[[#This Row],[Cost price]] -> #VALUE! | N21: Deliverd | O21: 12764966
A22: Jan | B22: Tamer | C22: 45677 | D22: =VLOOKUP(Table32[[#This Row],[Order Date]],'Calendars '!A22:C389,2,) -> W4 | E22: Tm Done | F22: 80.92 | G22: 3PL | H22: Flowers | I22: 3PL | K22: =(Table32[[#This Row],[Selling price]]-Table32[[#This Row],[Cost price]])/Table32[[#This Row],[Selling price]] -> 1 | L22: =Table3[[#This Row],[Selling price]]-Table3[[#This Row],[Cost price]] -> #VALUE! | N22: Deliverd | O22: 12764318
A23: Jan | B23: Tamer | C23: 45677 | D23: =VLOOKUP(Table32[[#This Row],[Order Date]],'Calendars '!A21:C388,2,) -> W4 | E23: Kenshō Mindful Communications | F23: 235.2 | G23: Gifting | H23: Flowers | I23: Corporate | K23: =(Table32[[#This Row],[Selling price]]-Table32[[#This Row],[Cost price]])/Table32[[#This Row],[Selling price]] -> 1 | L23: =Table3[[#This Row],[Selling price]]-Table3[[#This Row],[Cost price]] -> #VALUE! | N23: Deliverd in Egypt | P23: Egypt order
A24: Jan | B24: Tamer | C24: 45678 | D24: =VLOOKUP(Table32[[#This Row],[Order Date]],'Calendars '!A22:C389,2,) -> W4 | E24: Ominvest | F24: 37.325 | G24: Gifting | H24: Flowers & Chocolate | I24: Corporate | K24: =(Table32[[#This Row],[Selling price]]-Table32[[#This Row],[Cost price]])/Table32[[#This Row],[Selling price]] -> 1 | L24: =Table3[[#This Row],[Selling price]]-Table3[[#This Row],[Cost price]] -> #VALUE! | N24: Deliverd | O24: 12781313
A25: Jan | B25: Tamer | C25: 45678 | D25: =VLOOKUP(Table32[[#This Row],[Order Date]],'Calendars '!A22:C389,2,) -> W4 | E25: walk in | F25: 5.25 | G25: Gifting | H25: Flowers | I25: walk in | K25: =(Table32[[#This Row],[Selling price]]-Table32[[#This Row],[Cost price]])/Table32[[#This Row],[Selling price]] -> 1 | L25: =Table3[[#This Row],[Selling price]]-Table3[[#This Row],[Cost price]] -> #VALUE! | M25: Paid | N25: Deliverd | O25: 12780525 | P25: To Fatma POS
A26: Jan | B26: Tamer | C26: 45680 | D26: =VLOOKUP(Table32[[#This Row],[Order Date]],'Calendars '!A22:C389,2,) -> W4 | E26: OHRC | F26: 21.9 | G26: Event | H26: Flowers | I26: Gov | K26: =(Table32[[#This Row],[Selling price]]-Table32[[#This Row],[Cost price]])/Table32[[#This Row],[Selling price]] -> 1 | L26: =Table3[[#This Row],[Selling price]]-Table3[[#This Row],[Cost price]] -> #VALUE! | N26: Deliverd | O26: 12789816
A27: Jan | B27: Tamer | C27: 45680 | D27: =VLOOKUP(Table32[[#This Row],[Order Date]],'Calendars '!A22:C389,2,) -> W4 | E27: Ominvest | F27: 38 | G27: Gifting | H27: Flowers & Chocolate | I27: Corporate | K27: =(Table32[[#This Row],[Selling price]]-Table32[[#This Row],[Cost price]])/Table32[[#This Row],[Selling price]] -> 1 | L27: =Table3[[#This Row],[Selling price]]-Table3[[#This Row],[Cost price]] -> #VALUE! | N27: Deliverd | O27: 12783352
A28: Jan | B28: Tamer | C28: 45683 | D28: =VLOOKUP(Table32[[#This Row],[Order Date]],'Calendars '!A22:C389,2,) -> W5 | E28: HOUSE OF PIONEERS LLC | F28: 10342.5 | G28: Gifting | H28: Perfumes | I28: Corporate | K28: =(Table32[[#This Row],[Selling price]]-Table32[[#This Row],[Cost price]])/Table32[[#This Row],[Selling price]] -> 1 | L28: =Table3[[#This Row],[Selling price]]-Table3[[#This Row],[Cost price]] -> #VALUE! | M28: paid | N28: will Be Deliverd in Feb | O28: 12789030
A29: Jan | B29: Tamer | C29: 45683 | D29: =VLOOKUP(Table32[[#This Row],[Order Date]],'Calendars '!A29:C396,2,) -> W5 | E29: Bandera Exh | F29: 81 | G29: Event | H29: Flowers | I29: Event | K29: =(Table32[[#This Row],[Selling price]]-Table32[[#This Row],[Cost price]])/Table32[[#This Row],[Selling price]] -> 1 | L29: =Table3[[#This Row],[Selling price]]-Table3[[#This Row],[Cost price]] -> #VALUE! | M29: paid | N29: Deliverd | O29: 12820284
A30: Jan | B30: Tamer | C30: 45683 | D30: =VLOOKUP(Table32[[#This Row],[Order Date]],'Calendars '!A29:C396,2,) -> W5 | E30: Tm Done | F30: 16.508 | G30: 3PL | H30: Flowers | I30: 3PL | K30: =(Table32[[#This Row],[Selling price]]-Table32[[#This Row],[Cost price]])/Table32[[#This Row],[Selling price]] -> 1 | L30: =Table3[[#This Row],[Selling price]]-Table3[[#This Row],[Cost price]] -> #VALUE! | N30: Deliverd | O30: 12819357
A31: Jan | B31: Tamer | C31: 45686 | D31: =VLOOKUP(Table32[[#This Row],[Order Date]],'Calendars '!A29:C396,2,) -> W5 | E31: Ominvest | F31: 159 | G31: Gifting | H31: Chocolate | I31: Corporate | K31: =(Table32[[#This Row],[Selling price]]-Table32[[#This Row],[Cost price]])/Table32[[#This Row],[Selling price]] -> 1 | L31: =Table3[[#This Row],[Selling price]]-Table3[[#This Row],[Cost price]] -> #VALUE! | N31: Deliverd | O31: 12850048
A32: Jan | B32: Tamer | C32: 45686 | D32: =VLOOKUP(Table32[[#This Row],[Order Date]],'Calendars '!A29:C396,2,) -> W5 | E32: walk in | F32: 20 | G32: Gifting | H32: Flowers | I32: walk in | K32: =(Table32[[#This Row],[Selling price]]-Table32[[#This Row],[Cost price]])/Table32[[#This Row],[Selling price]] -> 1 | L32: =Table3[[#This Row],[Selling price]]-Table3[[#This Row],[Cost price]] -> #VALUE! | M32: paid | N32: Deliverd | O32: 12850270
A33: Jan | B33: Tamer | C33: 45686 | D33: =VLOOKUP(Table32[[#This Row],[Order Date]],'Calendars '!A29:C396,2,) -> W5 | E33: U.S. Embassy | F33: 48 | G33: Gifting | H33: Flowers | I33: Corporate | K33: =(Table32[[#This Row],[Selling price]]-Table32[[#This Row],[Cost price]])/Table32[[#This Row],[Selling price]] -> 1 | L33: =Table3[[#This Row],[Selling price]]-Table3[[#This Row],[Cost price]] -> #VALUE! | M33: paid | N33: Deliverd | O33: 12840935
A34: Jan | B34: Tamer | C34: 45688 | D34: =VLOOKUP(Table32[[#This Row],[Order Date]],'Calendars '!A34:C401,2,) -> W5 | E34: walk in | F34: 83.6509 | G34: Gifting | H34: Flowers | I34: walk in | K34: =(Table32[[#This Row],[Selling price]]-Table32[[#This Row],[Cost price]])/Table32[[#This Row],[Selling price]] -> 1 | L34: =Table3[[#This Row],[Selling price]]-Table3[[#This Row],[Cost price]] -> #VALUE! | M34: paid | N34: Deliverd | O34: 12871631
A35: Dec | B35: Tamer | C35: 31/12/2024 | D35: W1 | E35: Hatim Al Tai ( Al Roya ) | F35: 37.625 | G35: Gifting | H35: Flowers | I35: Birthday | K35: =(Table3[[#This Row],[Selling price]]-Table3[[#This Row],[Cost price]])/Table3[[#This Row],[Selling price]] -> #VALUE! | L35: =Table3[[#This Row],[Selling price]]-Table3[[#This Row],[Cost price]] -> #VALUE! | M35: paid (tamer Account ) | N35: Deliverd | O35: 12534011
A36: Total | F36: =SUBTOTAL(109,Table32[Selling price]) -> 20067.899 | J36: =SUBTOTAL(109,Table32[Cost price]) -> 4458.6 | K36: =SUBTOTAL(101,Table32[[Margin ]]) -> #VALUE! | L36: =SUBTOTAL(109,Table32[[Profit ]]) -> #VALUE!

Sheet OKRs
C1: Floward FY25 OKRs | F1: Q1 25 | R1: Q2 25 | S1: Q3 25 | T1: Q4 25
C2: Financial Figures in USD
C3: 29th December - 4th January
B4: # | C4: Objectives and Key Results | D4: Type | E4: Target | F4: WK1 | G4: WK2 | H4: WK3 | I4: WK4 | J4: WK5 | K4: WK6 | L4: WK7 | M4: WK8 | N4: WK9 | O4: WK10 | P4: WK11 | Q4: WK12
B5: 5 | C5: Establish our B2B and offline businesses as a major growth pillar for Floward
B6: 5.1 | C6: Secure at least x.x event deals at a total value of x.x over the quarter >> Monthly reporting | D6: Event | E6: 5 deals / $500k | F6: =GETPIVOTDATA("Selling price",Pivot!$A$3,"Week","W1","Type","3PL")*2.6 -> 0 | G6: =GETPIVOTDATA("Selling price",Pivot!$A$3,"Week","W2","Type","Event ")*2.6 -> 1144 | H6: =GETPIVOTDATA("Selling price",Pivot!$A$3,"Week","W3","Type","Event ")*2.6 -> 874.055 | I6: 21.9 | K6: 1373 | R6: 5 deals / $600k | S6: 5 deals / $700k | T6: 5 deals / $800k
B7: 5.1.1 | C7: Generate at least 500 Events leads >> Monthly reporting | E7: 500 | H7: =SUMIFS('JAN 2025'!F:F,'JAN 2025'!G:G,OKRs!D6,'JAN 2025'!D:D,OKRs!F4) -> 0
B8: 5.1.2 | C8: Increase conversion rate by 20% >> Monthly reporting | E8: 0.04
B9: 5.1.3 | C9: Stablish Social media engagment related content to reach 20000 >> Monthly reporting | E9: 20000
B10: 5.1.4 | C10: Increase the events offering options by 30% >> Monthly reporting | E10: 15
B11: 5.2 | C11: Secure at least x.x corporate gifting deals at a total value of x.x (Total Revenue) | D11: Gifting | E11: 15 deals / $1m | F11: =GETPIVOTDATA("Selling price",Pivot!$A$3,"Week","W1","Type","Gifting")*2.6 -> 19861.725 | G11: =GETPIVOTDATA("Selling price",Pivot!$A$3,"Week","W2","Type","Gifting")*2.6 -> 640.77 | H11: =GETPIVOTDATA("Selling price",Pivot!$A$3,"Week","W3","Type","Gifting")*2.6 -> 331.11 | I11: 80.58 | K11: 44 | R11: 15 deals / $1.2m | S11: 15 deals / $1.4m | T11: 15 deals / $1.6m
B12: 5.2.1 | C12: Generate at least 3700 corporate gifting leads | E12: 3700
B13: 5.2.2 | C13: Conversion rate | E13: 0.06
B14: 5.2.3 | C14: Increase AOV by 10% | E14: =120*1.1 -> 132
B15: 5.2.4 | C15: Increase the corporate gifting offering options by 30% | E15: 15
B16: 5.3 | C16: Launch x.x additional vending machine locations and achieve sales of x.x | D16: VM | E16: 20 locations / $3m | F16: =SUMIFS(Table32[Selling price],Table32[Type],OKRs!D16,Table32[Week],F4) -> 0 | G16: 0 | H16: 0 | I16: 0 | R16: 20 locations / $3.6m | S16: 20 locations / $4.2m | T16: 20 locations / $4.8m
B17: 5.3.1 | C17: Achive 95% uptime across all deployed vending machines | E17: 0.95
B18: 5.3.2 | C18: Complete installation process within 14 days of site approval | E18: 14
B19: 5.3.3 | C19: Achieve 95% fill rate across all deployed vending machines | E19: 0.95
B20: 5.3.4 | C20: Reduce transaction failure rates to below 2% | E20: 0.02
B21: 5.3.5 | C21: Implement 24/7 customer service hotline for VM issues to be resolved within 2 hours | E21: 2 hours
B22: 5.4 | C22: Develop and implement a scalable third-party white label partnership framework, targeting x new partnerships and contributing x.x in revenue >> Monthly reporting | D22: 3PL | E22: 5 partnerships / $750k | F22: =SUMIFS(Table32[Selling price],Table32[Type],OKRs!D22,Table32[Week],OKRs!F4) -> 0 | G22: =GETPIVOTDATA("Selling price",Pivot!$A$3,"Week","W2","Type","3PL")*2.6 -> 268.437 | H22: 0 | I22: 87.22 | R22: 5 partnerships / $900k | S22: 5 partnerships / $1m | T22: 5 partnerships / $1m
B23: 5.4.1 | C23: Ensure reach out coverage to all online food delivery companies for potential partnerships | E23: 1
B24: 5.4.2 | C24: Develop 3 new product lines weekly to imporve offerings >> Monthly reporting | E24: =3*12 -> 36
B25: 5.4.3 | C25: Implement a centralised partner portal to track sales and customer paterns to help improve offerings | E25: 1
I38: =J11*2.6 -> 0

Sheet Calendars 
A1: Date | B1: Week No | C1: Month | E1: Currency | F1: FORM | G1: Exchange rate to $
A2: 45655 | B2: W1 | C2: January | E2: SAR | F2: #VALUE! | G2: {=_FV(F2,"Price")} -> 0.2666
A3: 45656 | B3: W1 | C3: January
A4: 45657 | B4: W1 | C4: January
A5: 45658 | B5: W1 | C5: January
A6: 45659 | B6: W1 | C6: January
A7: 45660 | B7: W1 | C7: January
A8: 45661 | B8: W1 | C8: January
A9: 45662 | B9: W2 | C9: January
A10: 45663 | B10: W2 | C10: January
A11: 45664 | B11: W2 | C11: January
A12: 45665 | B12: W2 | C12: January
A13: 45666 | B13: W2 | C13: January
A14: 45667 | B14: W2 | C14: January
... A369: 46022 | B369: W53 | C369: December

Sheet March 2025
A1: Month | B1: Sales person | C1: Order Date | D1: Week | E1: Company Name | F1: Selling price | G1: Type | H1: Type Of Gift | I1: Business Type | J1: Cost price | K1: Margin | L1: Profit | M1: Payment status | N1: Delivery Status | O1: Order No | P1: Note
A2: March | B2: Tamer | C2: 45717 | E2: Lefties | F2: 215.25 | G2: Event | H2: Flowers | I2: Corporate | N2: Deliverd | O2: 13345844
A3: March | B3: Tamer | C3: 45718 | E3: ODP | F3: 53.025 | G3: Event | H3: Flowers | I3: Corporate | N3: Deliverd | O3: 13304134
A4: March | B4: Tamer | C4: 45722 | E4: Movenpic Hotel | F4: 304 | G4: Gifting | H4: Candel | I4: Corporate | M4: Paid | N4: Deliverd | O4: 13336742 | P4: Omna international Day
A5: March | B5: Tamer | C5: 45726 | E5: House Of Poiner | F5: 49 | G5: Gifting | H5: Flowers | I5: Corporate | M5: Paid | N5: Deliverd | O5: 13356157
A6: March | B6: Tamer | C6: 45727 | E6: Offline Sales | F6: 62 | G6: Flowers | H6: Flowers | I6: walk in | M6: Paid | N6: Deliverd | O6: 13363157
A7: March | B7: Tamer | C7: 45728 | E7: ODP | F7: 3810.45 | G7: Gifting | H7: Chocolate | I7: Corporate | N7: Deliverd | O7: 13379981
A8: March | B8: Tamer | C8: 45728 | E8: OIB | F8: 1580.25 | G8: Gifting | H8: Chocolate | I8: Corporate | M8: Paid | N8: Deliverd | O8: 13465045
A9: March | B9: Tamer | C9: 45728 | E9: DERMEDIC | F9: 1040.325 | G9: Gifting | H9: Chocolate | I9: Corporate | M9: Paid | N9: Deliverd | O9: 13451068
A10: March | B10: Tamer | C10: 45728 | E10: Tm Done | F10: 12.46 | G10: Flowers | H10: Flowers | I10: 3p | N10: Deliverd | O10: 13388875
A11: March | B11: Tamer | C11: 45732 | E11: OHRC | F11: 24 | G11: Flowers | H11: Flowers | I11: Gov | M11: Paid | N11: Deliverd | O11: 13419405
A12: March | B12: Tamer | C12: 45733 | E12: Blink Experience LLC. | F12: 269.85 | G12: Event | H12: Flowers | I12: Corporate | M12: Paid | N12: Deliverd | O12: 13427166
A13: March | B13: Tamer | C13: 45734 | E13: Talabat Order | F13: 132.391 | G13: Flowers | H13: Flowers | I13: 3p | N13: Deliverd | O13: 13438073
A14: March | B14: Tamer | C14: 45734 | E14: Oman Housing Bank | F14: 15.15 | G14: Flowers | H14: Flowers | I14: Corporate | M14: Paid | N14: Deliverd | O14: 13436823
A15: March | B15: Tamer | C15: 45734 | E15: Oman Housing Bank | F15: 15.15 | G15: Flowers | H15: Flowers | I15: Corporate | M15: Paid | N15: Deliverd | O15: 13436822
A16: March | B16: Tamer | C16: 45736 | E16: Amal Al Raisi | F16: 213.15 | G16: Flowers | H16: Flowers | I16: Corporate | M16: Paid | N16: Deliverd | O16: 13461743
A17: March | B17: Tamer | C17: 45737 | E17: Offline Sales | F17: 7 | G17: Flowers | H17: Flowers | M17: Paid | N17: Deliverd | O17: 13495398
A18: March | B18: Tamer | C18: 45737 | E18: Offline Sales | F18: 36 | G18: Flowers | H18: Flowers | I18: walk in | M18: Paid | N18: Deliverd | O18: 13490352
A19: March | B19: Tamer | C19: 45739 | E19: Synergy | F19: 1118.25 | G19: Gifting | H19: Chocolate | I19: walk in | M19: Paid | N19: Deliverd | O19: 13543901
A20: March | B20: Tamer | C20: 45739 | E20: ODP VIP | F20: 1375.5 | G20: Gifting | H20: Gift | I20: Corporate | N20: Deliverd | O20: 13544111
A21: March | B21: Tamer | C21: 45740 | E21: AFS Group | F21: 514 | G21: Gifting | H21: Chocolate | I21: Corporate | N21: Deliverd | O21: 13525962
C22: 45741 | E22: Ominvest | F22: 289.8 | G22: Gifting | H22: Chocolate | I22: Corporate | M22: Paid | N22: Deliverd | O22: 13547256-13547258-
A23: March | B23: Tamer | C23: 45741 | E23: Ominvest | F23: 4782.5 | G23: Gifting | H23: Chocolate | I23: Corporate | M23: Paid | N23: Deliverd | O23: 13798198
A24: March | B24: Tamer | C24: 45742 | E24: ODP Malik | F24: 76.757 | G24: Gifting | H24: Chocolate & flowers | I24: Corporate | N24: Deliverd | O24: 13556495
A25: March | B25: Tamer | C25: 45742 | E25: Mubashir | F25: 215.25 | G25: Flowers | H25: Chocolate & flowers | I25: Corporate | M25: Paid | N25: Deliverd | O25: 13554333
A26: March | B26: Tamer | C26: 45743 | E26: Haneen ODP | F26: 28.875 | G26: Gifting | H26: Chocolate | I26: personal | M26: Paid | N26: Deliverd | O26: 13555251
A27: March | B27: Tamer | C27: 45743 | E27: Haneen ODP | F27: 15.225 | G27: Gifting | H27: Chocolate | I27: personal | M27: Paid | N27: Deliverd | O27: 13556058
A28: March | B28: Tamer | C28: 45743 | E28: Majda OIB | F28: 131.25 | G28: Gifting | H28: Chocolate | I28: personal | M28: Paid | N28: Deliverd | O28: 13566773
A29: March | B29: Tamer | C29: 45743 | E29: Ominvest Dubi Order | F29: 304 | G29: Gifting | H29: Chocolate | I29: Corporate | M29: Paid | N29: Deliverd | O29: 13547464-13545238-13547388-13547319
A30: March | B30: Tamer | C30: 45745 | E30: Synergy | F30: 1212.75 | G30: Flowers | H30: Flowers | I30: Corporate | M30: Paid | N30: Deliverd | O30: 13603043
A31: March | B31: Tamer | C31: 45743 | E31: Offline Sales | F31: 35 | G31: Flowers | H31: Flowers | I31: walk in | M31: Paid | N31: Deliverd | O31: 13568435
A32: March | B32: Tamer | C32: 45745 | E32: Talabat Order | F32: 101 | G32: Flowers | H32: Flowers | I32: 3p | N32: Deliverd | O32: 13604425
A33: March | B33: Tamer | C33: 45745 | E33: Offline Sales | F33: 95 | G33: Flowers | H33: Flowers | I33: walk in | M33: Paid | N33: Deliverd | O33: 13602182
A34: March | B34: Tamer | C34: 45745 | E34: Tm Done | F34: 5.1 | G34: Flowers | H34: Flowers | I34: 3p | N34: Deliverd | O34: 13601975
A35: March | B35: Tamer | C35: 45746 | E35: Mubashir | F35: 23 | G35: Flowers | H35: Flowers | I35: Corporate | M35: Paid | N35: Deliverd | O35: 13630542
A36: March | B36: Tamer | C36: 45746 | E36: Offline Sales | F36: 17 | G36: Flowers | H36: Flowers | I36: walk in | M36: Paid | N36: Deliverd | O36: 13504696
A37: March | B37: Tamer | C37: 45744 | E37: Ominvest | F37: 61.575 | G37: Gifting | H37: Chocolate & flowers | I37: Corporate | M37: Paid | N37: Deliverd | O37: 13586104 | P37: Sohar Order
A38: March | B38: Tamer | C38: 45746 | E38: Talabat Order | F38: 62.23 | G38: Flowers | H38: Flowers | I38: 3p | N38: Deliverd | O38: 13632529 | P38: Sohar Order
A39: Total | F39: =SUM(F2:F38) -> 18303.513

Sheet Sheet6

Sheet April 2025 
A1: Month | B1: Sales person | C1: Order Date | D1: Week | E1: Company Name | F1: Selling price | G1: Type | H1: Type Of Gift | I1: Business Type | J1: Cost price | K1: Margin | L1: Profit | M1: Payment status | N1: Delivery Status | O1: Order No | P1: Note
A2: April | B2: Tamer | C2: 45812 | E2: walk in Customer | F2: 36 | G2: walk in | H2: Flowers | I2: walk in | M2: Paid | N2: Deliverd | O2: 13696374
A3: April | B3: Tamer | C3: 45812 | E3: TM Done | F3: 5.09 | G3: 3P | H3: Flowers | I3: 3P | N3: Deliverd | O3: 13635164
A4: April | B4: Tamer | C4: 45842 | E4: Talabat | F4: 149.885 | G4: 3P | H4: Flowers | I4: 3P | N4: Deliverd | O4: 13703473
A5: April | B5: Tamer | C5: 45842 | E5: Talabat | F5: 49.663 | G5: 3P | H5: Flowers | I5: 3P | N5: Deliverd | O5: 13702956
A6: April | B6: Tamer | C6: 45873 | E6: Talabat Sohar | F6: 103 | G6: 3P | H6: Flowers | I6: 3P | N6: Deliverd | O6: 13710331
A7: April | B7: Tamer | C7: 04/13/2025 | E7: Talabat | F7: 91.575 | G7: 3P | H7: Flowers | I7: 3P | N7: Deliverd | O7: 13768526
A8: April | B8: Tamer | C8: 04/13/2025 | E8: Arab Open Univeristy | F8: 156 | G8: event | H8: Flowers | I8: Corporate | M8: Paid | N8: Deliverd | O8: 13768036
A9: April | B9: Tamer | C9: 04/14/2025 | E9: Talabat Sohar | F9: 49 | G9: 3P | H9: Flowers | I9: 3P | N9: Deliverd | O9: 13776579
A10: April | B10: Tamer | C10: 04/15/2025 | E10: ODP | F10: 39.375 | G10: Gift | H10: Flowers | I10: Corporate | N10: Deliverd | O10: 13778963
A11: April | C11: 04/15/2025 | E11: Lovera Café | F11: 30 | G11: event | H11: Flowers | I11: Corporate | N11: Deliverd | O11: 13788198
A12: April | B12: Tamer | C12: 04/15/2025 | E12: Lovera Café | F12: 60 | G12: event | H12: Flowers | I12: Corporate | N12: Deliverd | O12: 13804618
A13: April | B13: Tamer | C13: 04/16/2025 | E13: Styles For Event | F13: 24 | G13: event | H13: Flowers | I13: Corporate | M13: Paid | N13: Deliverd | O13: 13794585
A14: April | B14: Tamer | C14: 04/17/2025 | E14: Majid Al Futtim | F14: 454.65 | G14: event | H14: Flowers | I14: Corporate | M14: Paid | N14: Deliverd | O14: 13807654
A15: April | B15: Tamer | C15: 04/17/2025 | E15: Mohamed Al Yahmadi | F15: 164.05 | G15: Gift | H15: Flowers | I15: Corporate | N15: Deliverd | O15: 13804972
A16: April | B16: Tamer | C16: 04/17/2025 | E16: ODP | F16: 45.652 | G16: Gift | H16: Flowers | I16: Corporate | N16: Deliverd | O16: 13803555
B17: Tamer | C17: 04/17/2025 | E17: NBO | F17: 137.228 | G17: event | H17: Flowers | I17: Corporate | N17: Deliverd | O17: 13704238
A18: April | B18: Tamer | C18: 04/23/1900 | E18: Talabat | F18: 220.709 | G18: 3P | H18: Flowers | I18: 3P | N18: Deliverd | O18: 13856042
A19: April | B19: Tamer | C19: 04/23/1900 | E19: OHRC | F19: 27.09 | G19: event | H19: Flowers | I19: Corporate | M19: Paid | N19: Deliverd | O19: 13860538
A20: April | B20: Tamer | C20: 04/23/1900 | E20: Lovera Café | F20: 12 | G20: event | H20: Flowers | I20: Corporate | N20: Deliverd | O20: 13855362
A21: April | B21: Tamer | C21: 04/23/1900 | E21: Lovera Café Sohar | F21: 7.575 | G21: event | H21: Flowers | I21: Corporate | N21: Deliverd | O21: 13855310
A22: April | B22: Tamer | C22: 04/23/2025 | E22: Al Roya | F22: 81.9 | G22: event | H22: Flowers | I22: Corporate | N22: Deliverd | O22: 3860633
A23: April | B23: Tamer | C23: 04/23/2025 | E23: HOUSE OF PIONEERS LLC | F23: 2204 | G23: Gift | H23: Flowers | I23: Corporate | M23: Paid | N23: Deliverd | O23: 13846263
A24: April | B24: Tamer | C24: 04/24/2025 | E24: Talabat Sohar | F24: 28.319 | G24: 3P | H24: Flowers | I24: 3P | N24: Deliverd | O24: 13856599
A25: April | B25: Tamer | C25: 04/27/2025 | E25: Offline Sales | F25: 115 | G25: walk in | H25: Flowers | I25: walk in | M25: Paid | N25: Deliverd | O25: 13902365
A26: April | B26: Tamer | C26: 04/27/2025 | E26: Ministry of Commerce, Industry and Investment Promotion. | F26: 60 | G26: event | H26: Flowers | I26: Gov | M26: paid with tamer | N26: Deliverd | O26: 13903046
A27: April | B27: Tamer | C27: 04/27/2025 | E27: Hani Al Kindy | F27: 51 | G27: walk in | H27: Flowers | I27: walk in | N27: Deliverd | O27: 13929299
A28: April | B28: Tamer | C28: 04/27/2025 | E28: Talabat | F28: 174 | G28: 3P | H28: Flowers | I28: 3P | N28: Deliverd | O28: 13926225
C29: 04/29/2025 | E29: Talabat Sohar | F29: 18.204 | G29: 3P | H29: Flowers | I29: 3P | N29: Deliverd | O29: 13927837
A30: April | B30: Tamer | C30: 04/30/2025 | E30: Ominvest | F30: 41.625 | G30: Gift | H30: Flowers | I30: Corporate | M30: Paid | N30: Deliverd | O30: 13911313
A31: April | B31: Tamer | C31: 04/30/2025 | E31: DERMEDIC | F31: 48 | G31: event | H31: Flowers | I31: Corporate | M31: Paid | N31: Deliverd | O31: 13918835
A32: April | B32: Tamer | C32: 04/30/2025 | E32: NBO | F32: 255.15 | G32: event | H32: Flowers | I32: Corporate | M32: Paid | N32: Deliverd | O32: 13936257
A33: April | B33: Tamer | C33: 04/30/2025 | E33: Offline Sales | F33: 36.6 | G33: walk in | H33: Flowers | I33: walk in | M33: Paid | N33: Deliverd | O33: 13912995
A34: April | B34: Tamer | C34: 04/30/2025 | E34: Lovera Café | F34: 12 | G34: event | H34: Flowers | I34: Corporate | N34: Deliverd | O34: 13901159
A35: April | B35: Tamer | C35: 04/30/2025 | E35: Lovera Café Sohar | F35: 7.575 | G35: event | H35: Flowers | I35: Corporate | N35: Deliverd | O35: 13901188
A36: April | B36: Tamer | C36: 04/30/2025 | E36: Talabat | F36: 22.871 | G36: 3P | H36: Flowers | I36: 3P | N36: Deliverd | O36: 13937934
A37: April | B37: Tamer | C37: 04/30/2025 | E37: Offline Sales | F37: 15 | G37: walk in | H37: Flowers | I37: walk in | M37: Paid | N37: Deliverd | O37: 13941303
F38: =SUM(F2:F37) -> 5033.786

Sheet May 2025 
A1: Month | B1: Sales person | C1: Order Date | D1: Week | E1: Company Name | F1: Selling price | G1: Type | H1: Type Of Gift | I1: Business Type | J1: Cost price | K1: Margin | L1: Profit | M1: Payment status | N1: Delivery Status | O1: Order No | P1: Note
A2: May | B2: Tamer | C2: 45662 | E2: HOUSE OF PIONEERS LLC | F2: 38.1 | G2: Corporate | H2: Flowers | I2: Corporate | M2: Paid | N2: Deliverd | O2: 13959023
A3: May | B3: Tamer | C3: 45662 | E3: Ominvest | F3: 30 | G3: Corporate | H3: Chocolate | I3: Corporate | M3: Paid | N3: Deliverd | O3: 13959023
A4: May | B4: Tamer | C4: 45693 | E4: Lovera Café | F4: 13 | G4: Corporate | H4: Flowers | I4: Subscription | N4: Deliverd | O4: 13984811
A5: May | B5: Tamer | C5: 45721 | E5: Styles For Event | F5: 194.25 | G5: Event | H5: Flowers | I5: Event | M5: Paid | N5: Deliverd | O5: 13958575
A6: May | B6: Tamer | C6: 45721 | E6: Styles For Event | F6: 44.1 | G6: Event | H6: Flowers | I6: Event | M6: Paid | N6: Deliverd | O6: 13958431
A7: May | B7: Tamer | C7: 45752 | E7: Oman Data Park | F7: 72.75 | G7: Corporate | H7: Flowers | I7: Corporate | N7: Deliverd | O7: 13985705
A8: May | B8: Tamer | C8: 45843 | E8: Movenpic Hotel | F8: 847.79 | G8: Corporate | H8: Flowers | I8: Event | M8: Paid | N8: Deliverd | O8: 14006896
A9: May | B9: Tamer | C9: 45966 | E9: Aster Hospital | F9: 180 | G9: Event | H9: Flowers | I9: Event | M9: Paid | N9: Deliverd | O9: 14061456
A10: May | B10: Tamer | C10: 45966 | E10: Talabt For Muscat | F10: 45.187 | G10: 3P | H10: Flowers | I10: 3P | N10: Deliverd | O10: 14071518
A11: May | B11: Tamer | C11: 45966 | E11: Rashid | F11: 30 | G11: Walk in | H11: Flowers | I11: Walk in | M11: Paid | N11: Deliverd | O11: 14069737
A12: May | B12: Tamer | C12: 45996 | E12: OCEC | F12: 21 | G12: Corporate | H12: Flowers | I12: Corporate | N12: Deliverd | O12: 14063658
A13: May | B13: Tamer | C13: 05/13/2025 | E13: Talabt For Sohar | F13: 137.346 | G13: 3P | H13: Flowers | I13: 3P | N13: Deliverd | O13: 14061473
A14: May | B14: Tamer | C14: 05/13/2025 | E14: Talabt For Muscat | F14: 142.906 | G14: 3P | H14: Flowers | I14: 3P | N14: Deliverd | O14: 14060339
A15: May | B15: Tamer | C15: 05/13/2025 | E15: OCEC | F15: 63 | G15: Corporate | H15: Flowers | I15: Corporate | N15: Deliverd | O15: 14075142
A16: May | C16: 05/14/2025 | E16: ODP | F16: 50 | G16: Corporate | H16: Flowers | I16: Corporate | N16: Deliverd | O16: 14096727
A17: May | B17: Tamer | C17: 05/15/2025 | E17: Graduation UTAS | F17: 338.1 | G17: Graduation | H17: Flowers | I17: Event | M17: Paid | N17: Deliverd | O17: 14108654
A18: May | B18: Tamer | C18: 05/17/2025 | E18: Styles For Event | F18: 183.75 | G18: Corporate | H18: Flowers | I18: Corporate | M18: Paid | N18: Deliverd | O18: 14109604
A19: May | B19: Tamer | C19: 05/18/2025 | E19: Ooredoo | F19: 73.5 | G19: Corporate | H19: Flowers | I19: Corporate | N19: Deliverd
A20: May | B20: Tamer | C20: 05/18/2025 | E20: Talabat Sohar | F20: 48.27 | G20: 3P | H20: Flowers | I20: 3P | N20: Deliverd | O20: 14135521
A21: May | B21: Tamer | C21: 05/19/2025 | E21: OCEC | F21: 64 | G21: Event | H21: Flowers | I21: Event | N21: Deliverd | O21: 14144444
A22: May | B22: Tamer | C22: 05/20/2025 | E22: Ooredoo | F22: 65.625 | G22: Corporate | H22: Flowers | I22: Corporate | N22: Deliverd | O22: 14154363
A23: May | B23: Tamer | C23: 05/20/2025 | E23: Oliban | F23: 47.25 | G23: Corporate | H23: Flowers | I23: Corporate | M23: Paid | N23: Deliverd | O23: 14156599
A24: May | B24: Tamer | C24: 05/21/2025 | E24: Arab Open Univeristy | F24: 352.8 | G24: Event | H24: Flowers | I24: Event | N24: Deliverd | O24: 14167191
A25: May | B25: Tamer | C25: 05/21/2025 | E25: Sabeen Event | F25: 257.25 | G25: Event | H25: Flowers | I25: Event | N25: Deliverd | O25: 14167120
A26: May | B26: Tamer | C26: 05/21/2025 | E26: Walk in | F26: 15 | G26: Walk in | H26: Flowers | I26: Walk in | M26: Paid | N26: Deliverd | O26: 14164373
A27: May | B27: Tamer | C27: 05/21/2025 | E27: Sabeen Event | F27: 31.5 | G27: Event | H27: Flowers | I27: Event | N27: Deliverd | O27: 14219015
A28: May | B28: Tamer | C28: 05/25/2025 | E28: MIS | F28: 231 | G28: Event | H28: Flowers | I28: Event | M28: Paid | N28: Deliverd | O28: 14207750
A29: May | B29: Tamer | C29: 05/25/2025 | E29: ODP | F29: 29.625 | G29: Corporate | H29: Flowers | I29: Corporate | N29: Deliverd | O29: 14207443
A30: May | B30: Tamer | C30: 05/25/2025 | E30: Arab Open Univeristy | F30: 251.8 | G30: Graduation | H30: Flowers | I30: Offline | M30: Paid | N30: Deliverd | O30: 14206740
A31: May | B31: Tamer | C31: 05/26/2025 | E31: OCEC | F31: 103.95 | G31: Event | H31: Flowers | I31: Event | N31: Deliverd | O31: 14218345
A32: May | B32: Tamer | C32: 05/26/2025 | E32: Hatim aAl Tai | F32: 30 | G32: Corporate | H32: Flowers | I32: Corporate | M32: paid with tamer | N32: Deliverd | O32: 14222768
A33: May | B33: Tamer | C33: 05/26/2025 | E33: Talabat | F33: 119.556 | G33: 3P | H33: Flowers | I33: 3P | N33: Deliverd | O33: 14218232
A34: May | B34: Tamer | C34: 05/26/2025 | E34: Talabat Sohar | F34: 23.004 | G34: 3P | H34: Flowers | I34: 3P | N34: Deliverd | O34: 14218453
A35: May | B35: Tamer | C35: 05/27/2025 | E35: OQ8 | F35: 6204.03 | G35: Corporate | H35: Chocolate | I35: Corporate | N35: Deliverd | O35: 14219057
A36: May | B36: Tamer | C36: 05/27/2025 | E36: OCEC | F36: 64.05 | G36: Event | H36: Flowers | I36: Event | N36: Deliverd | O36: 14220264
A37: May | B37: Tamer | C37: 05/27/2025 | E37: Hatim aAl Tai | F37: 30 | G37: Corporate | H37: Flowers | I37: Corporate | M37: paid with tamer | N37: Deliverd | O37: 14235785
A38: May | B38: Tamer | C38: 05/28/2025 | E38: Alandalus Private School Muscat | F38: 1049.457 | G38: Event | H38: Flowers | I38: Event | M38: Paid | N38: Deliverd | O38: 14244813
A39: May | B39: Tamer | C39: 05/28/2025 | E39: OCEC | F39: 88.2 | G39: Event | H39: Flowers | I39: Event | N39: Deliverd | O39: 14236387
A40: May | B40: Tamer | C40: 05/28/2025 | E40: Offline Sales | F40: 123.99 | G40: Walk in | H40: Flowers | I40: Walk in | M40: Paid | N40: Deliverd | O40: 14248099
...

Sheet June 2025 
A1: Sales person | B1: Order Date | C1: Week | D1: Company Name | E1: Selling price | F1: Type | G1: Type Of Gift | H1: Business Type | I1: Cost price | J1: Margin | K1: Profit | L1: Payment status | M1: Delivery Status | N1: Order No
A2: Tamer | B2: 45663 | D2: Ooredoo Bussines | E2: 1260 | F2: Corporate | G2: Chocolate | H2: Corporate | M2: Deliverd | N2: 14290048 | O2: 14324265
A3: Tamer | B3: 45663 | D3: ODP | E3: 1916.25 | F3: Corporate | G3: Flowers & Gift | H3: Corporate | M3: Deliverd | N3: 14298600
A4: Tamer | B4: 45663 | D4: Mubashir | E4: 24 | F4: Corporate | G4: Flowers | H4: Corporate | M4: Deliverd | N4: 14298410
A5: Tamer | B5: 45663 | D5: Lovera Café | E5: 6.825 | F5: Corporate | G5: Flowers | H5: Corporate | M5: Deliverd | N5: 14310446
A6: Tamer | B6: 45694 | D6: JW Towel | E6: 540.75 | F6: Corporate | G6: Chocolate | H6: Corporate | L6: Paid | M6: Deliverd | N6: 14298979
A7: Tamer | B7: 45694 | D7: Styless For event | E7: 100 | F7: Corporate | G7: Flowers | H7: Corporate | M7: Deliverd | N7: 14313172
A8: Tamer | B8: 45722 | D8: walk In Rasha | E8: 14.5 | F8: Walk in | G8: Flowers | H8: Walk in | L8: Paid With Tamer | M8: Deliverd | N8: 14324173
A9: Tamer | B9: 45753 | D9: Talalbat | E9: 66.365 | F9: 3P | G9: Flowers | H9: 3P | M9: Deliverd | N9: 14334725
A10: Tamer | B10: 45753 | D10: OIB | E10: 1202.25 | F10: Corporate | G10: Chocolate | H10: Corporate | M10: Deliverd | N10: 14324112
A11: Tamer | B11: 45753 | D11: OHB | E11: 78.225 | F11: Corporate | G11: Chocolate | H11: Corporate | M11: Deliverd | N11: 14332931
A12: Tamer | B12: 45753 | D12: Talalbat Sohar | E12: 16.301 | F12: 3P | G12: Flowers | H12: 3P | M12: Deliverd | N12: 14335796
A13: Tamer | B13: 45936 | D13: Talalbat | E13: 93.345 | F13: 3P | G13: Flowers | H13: 3P | M13: Deliverd | N13: 14418037 | P13: 14433126
A14: Tamer | B14: 45936 | D14: Ooredoo Bussines | E14: 70.075 | F14: Corporate | G14: Chocolate | H14: Corporate | M14: Deliverd | N14: 14416581
A15: Tamer | B15: 45936 | D15: Talalbat Sohar | E15: 55.425 | F15: 3P | G15: Flowers | H15: 3P | M15: Deliverd | N15: 14418126
A16: Tamer | B16: 45967 | D16: ABQ | E16: 76.65 | F16: Corporate | G16: Chocolate | H16: Corporate | M16: Deliverd | N16: 14429591 | P16: 14433781
A17: Tamer | B17: 45967 | D17: Ominvest | E17: 213 | F17: Corporate | G17: Chocolate | H17: Corporate | M17: Deliverd | N17: 14432870 | O17: 14433062 | P17: 14433126
A18: Tamer | B18: 45967 | D18: ODP | E18: 22.95 | F18: Corporate | G18: Flowers | H18: Corporate | M18: Deliverd | N18: 14433349
A19: Tamer | B19: 45997 | D19: Ooredoo Bussines | E19: 100 | F19: Corporate | G19: Flowers | H19: Corporate | M19: Deliverd | N19: 14433881 | O19: 14433849
A20: Tamer | B20: 45997 | D20: Al Zubair | E20: 85 | F20: Corporate | G20: Flowers | H20: Corporate | L20: Paid Transfer | M20: Deliverd | N20: 14418911 | O20: Dubi Order
A21: Tamer | B21: 45997 | D21: Mirna | E21: 38 | F21: Corporate | G21: Flowers | H21: Corporate | L21: Paid | M21: Deliverd | N21: 14442000
A22: Tamer | B22: 45997 | D22: Lovera Café | E22: 10 | F22: Corporate | G22: Flowers | H22: Corporate | M22: Deliverd | N22: 14444706
A23: Tamer | B23: 06/14/2025 | D23: OHRC | E23: 77.625 | F23: Corporate | G23: Flowers | H23: Corporate | M23: Deliverd | N23: 14460830
A24: Tamer | B24: 06/16/2025 | D24: Hani Al Kindi | E24: 50 | F24: Corporate | G24: Flowers | H24: Corporate | L24: Paid POS | M24: Deliverd | N24: 14493090
A25: Tamer | B25: 06/16/2025 | D25: ABQ | E25: 271 | F25: Corporate | G25: Chocolate | H25: Corporate | M25: Deliverd | N25: 14490970
A26: Tamer | B26: 06/17/2025 | D26: Oman Investment Bank | E26: 52.1 | F26: Corporate | G26: Flowers | H26: Corporate | M26: Deliverd | N26: 14504549
A27: Tamer | B27: 06/18/2025 | D27: OQ8 | E27: 1149.435 | F27: Corporate | G27: Chocolate | H27: Corporate | M27: Deliverd | N27: 14515404
A28: Tamer | B28: 06/19/2025 | D28: ABQ | E28: 397.95 | F28: Corporate | G28: Chocolate | H28: Corporate | M28: Deliverd | N28: 14491099
A29: Tamer | B29: 06/19/2025 | D29: ABQ | E29: 242.025 | F29: Corporate | G29: Chocolate | H29: Corporate | M29: Deliverd | N29: 14491038
A30: Tamer | B30: 06/19/2025 | D30: Talalbat | E30: 118.383 | F30: 3P | G30: Flowers | H30: 3P | M30: Deliverd | N30: 14584420
A31: Tamer | B31: 06/22/2025 | D31: OCEC | E31: 64.5 | F31: Corporate | G31: Flowers | H31: Corporate | M31: Deliverd | N31: 14555896
A32: Tamer | B32: 06/22/2025 | D32: NBO | E32: 27 | F32: Corporate | G32: Flowers | H32: Corporate | M32: Deliverd | N32: 14547509
A33: Tamer | B33: 06/22/2025 | D33: ODP | E33: 107.25 | F33: Corporate | G33: Flowers | H33: Corporate | M33: Deliverd | N33: 14526470
A34: Tamer | B34: 06/23/2025 | D34: OCEC | E34: 37.8 | F34: Corporate | G34: Flowers | H34: Corporate | M34: Deliverd | N34: 14556265
A35: Tamer | B35: 06/24/2025 | D35: ABQ | E35: 101.325 | F35: Corporate | G35: Chocolate | H35: Corporate | M35: Deliverd | N35: 14566572
A36: Tamer | B36: 06/24/2025 | D36: Lovera Café | E36: 10 | F36: Corporate | G36: Flowers | H36: Corporate | M36: Deliverd | N36: 14593309
... A38: Tamer | B38: 06/28/2025 | D38: M.Housing | E38: 1393.875 | F38: Gov | G38: Plants | H38: Gov | M38: Deliverd | N38: 14645183
B39: 06/28/2025 | D39: Mohamed Al Yahmadi | E39: 117.627 | F39: Corporate | G39: Flowers & Gift | H39: Corporate | M39: Deliverd | N39: 14635820
B40: 06/29/2025 | D40: Offline Sales | E40: 170.067 | F40: Walk in | G40: Flowers | H40: Walk in | M40: Deliverd | N40: 14635820
B41: 06/30/2025 | D41: Offline Sales | E41: 26 | F41: Walk in | G41: Flowers | H41: Walk in | M41: Deliverd | N41: 14661745
...

Sheet July 
A1: Month | B1: Sales person | C1: Order Date | D1: Week | E1: Company Name | F1: Selling price | G1: Type | H1: Type Of Gift | I1: Business Type | J1: Cost price | K1: Margin | L1: Profit | M1: Payment status | N1: Delivery Status | O1: Order No
A2: July | B2: Tamer | C2: 45839 | E2: Lovera Café | F2: 7.5 | G2: Corporate | H2: Flowers | I2: Corporate | N2: Deliverd | O2: 14767206
A3: July | B3: Tamer | C3: 45839 | E3: Offline Sales | F3: 143.6 | G3: offline Sales | H3: Flowers | I3: offline Sales | N3: Deliverd | O3: 14914973
A4: July | B4: Tamer | C4: 45839 | E4: Ominvest | F4: 226.8 | G4: Corporate | H4: Chocolate | I4: Corporate | N4: Deliverd | O4: 14917206
A5: July | B5: Tamer | C5: 45840 | E5: Styles For Event | F5: 14.7 | G5: Corporate | H5: Flowers | I5: Corporate | N5: Deliverd | O5: 14681120
A6: July | B6: Tamer | C6: 45844 | E6: Styles For Event | F6: 36.75 | G6: Corporate | H6: Flowers | I6: Corporate | N6: Deliverd | O6: 14724864
A7: July | B7: Tamer | C7: 45846 | E7: OHRC | F7: 59.325 | G7: GOV | H7: Flowers | I7: Event | N7: Deliverd | O7: 14743834
A8: July | B8: Tamer | C8: 45848 | E8: ABQ | F8: 10 | G8: Corporate | H8: Flowers | I8: Corporate | N8: Deliverd | O8: 14764578
A9: July | B9: Tamer | C9: 45848 | E9: PDO Sales | F9: 52 | G9: Corporate | H9: Flowers | I9: Event | N9: Deliverd | O9: 14764470
A10: July | B10: Tamer | C10: 45848 | E10: Sabeen | F10: 87.5 | G10: Corporate | H10: Flowers | I10: Corporate | M10: Paid | N10: Deliverd | O10: 14762307
A11: July | B11: Tamer | C11: 45851 | E11: Talabat Muscat | F11: 106 | G11: 3P | H11: Flowers | I11: 3P | N11: Deliverd | O11: 14790089
A12: July | B12: Tamer | C12: 45851 | E12: Talabat Sohar | F12: 56.94 | G12: 3P | H12: Flowers | I12: 3P | N12: Deliverd | O12: 14789994
A13: July | C13: 45854 | E13: Al Roya | F13: 31.5 | G13: Corporate | H13: Flowers | I13: Corporate | N13: Deliverd | O13: 14820386
A14: July | B14: Tamer | C14: 45854 | E14: Lovera Café | F14: 7.875 | G14: Corporate | H14: Flowers | I14: Corporate | N14: Deliverd | O14: 14817224
A15: July | B15: Tamer | C15: 45857 | E15: Fatma Al Rahibi | F15: 26.4 | G15: Corporate | H15: Flowers | I15: Corporate | M15: Paid POS invoice No 422 | N15: Deliverd | O15: 14836528
A16: July | B16: Tamer | C16: 45858 | E16: Hatim Al Tai | F16: 33 | G16: Corporate | H16: Flowers | I16: Corporate | M16: Transfer To Tamer | N16: Deliverd | O16: 14853626
A17: July | B17: Tamer | C17: 45858 | E17: Talabat Muscat | F17: 50.758 | G17: 3P | H17: Flowers | I17: 3P | N17: Deliverd | O17: 14851638
A18: July | B18: Tamer | C18: 45858 | E18: Talabat Sohar | F18: 14.9 | G18: 3P | H18: Flowers | I18: 3P | N18: Deliverd | O18: 14852560
A19: July | B19: Tamer | C19: 45859 | E19: Ominvest | F19: 64.65 | G19: Corporate | H19: Flowers | I19: Corporate | N19: Deliverd | O19: 14853497
